non_common_sense_row
Traceback (most recent call last):
  File "/homes/rebboud/.local/lib/python3.8/site-packages/pandas/core/indexes/base.py", line 3621, in get_loc
    return self._engine.get_loc(casted_key)
  File "pandas/_libs/index.pyx", line 136, in pandas._libs.index.IndexEngine.get_loc
  File "pandas/_libs/index.pyx", line 163, in pandas._libs.index.IndexEngine.get_loc
  File "pandas/_libs/hashtable_class_helper.pxi", line 5198, in pandas._libs.hashtable.PyObjectHashTable.get_item
  File "pandas/_libs/hashtable_class_helper.pxi", line 5206, in pandas._libs.hashtable.PyObjectHashTable.get_item
KeyError: 'parsed_complete_sentence'

The above exception was the direct cause of the following exception:

Traceback (most recent call last):
  File "refine.py", line 33, in <module>
    common_sense_embeddings = [model(tokenizer(text, return_tensors='pt').input_ids.to(device)).last_hidden_state.mean(dim=1).detach().cpu().numpy() for text in non_common_sense_group['parsed_complete_sentence']]
  File "/homes/rebboud/.local/lib/python3.8/site-packages/pandas/core/frame.py", line 3505, in __getitem__
    indexer = self.columns.get_loc(key)
  File "/homes/rebboud/.local/lib/python3.8/site-packages/pandas/core/indexes/base.py", line 3623, in get_loc
    raise KeyError(key) from err
KeyError: 'parsed_complete_sentence'
